Workbook
Name FromArray_1: _xlfn.ANCHORARRAY(ForWeb!$G$3)

Sheet Read Me
B2: ASUS User Instruction | E2: How to update
E3: PM
B4: Tab: | C4: Usage | E4: Step 1: Download & Paste raw data into column G of RAW.KSP.Link, starting from the first empty row.
B5: Search-Table: | C5: Use this tab to test if your product info is correct and able to be searched | E5: Step 2: Fill in Tagline and KSP in columns C and D of the RAW.KSP.Link sheet.
B6: Raw.KSP.Link | C6: Spec sheet PM updated from EIP-Ecom-PreConfig | E6: Step 3: Notify MKT to upload material file links for the newly added products.
B7: Auto-NX | C7: Sheet containing formulas to auto-generate text in specific format for NX | E7: Step 4: Once MKT report is done, export ForWeb as CSV (UTF-8) and replace the old file on GitHub.
B8: Auto-AIO | C8: Sheet containing formulas to auto-generate text in specific format for AIO | E8: Step 5: Check if the website is working after 3 minutes (include the SPEC and Link bottom)
B9: Auto-PF | C9: Sheet containing formulas to auto-generate text in specific format for PF
B10: ForWeb | C10: Data for export to Website and Search-Table as data resource
B11: MKT name rule | C11: If MKT name is not auto-generated in RAW,KSP,Link, fill it in manually.
E12: MKT
E13: Step 1: Once PM requests, upload the corresponding Google Drive link into column G of RAW.KSP.Link
B14: Website Link | C14: https://astonlu.github.io/AplusContent/ | E14: Step 2: Report back to PM once done
B21: INTERNAL USE ONLY. DO NOT SHARE THIS FILE TO PARTNERS.

Sheet Search-Table
B3: B9406CAA-THX7312WS | C3: ⭠Please input the model name e.g. B1402CVA-NK7110X
B5: Product Name | C5: =IFERROR(INDEX(ForWeb!$C$2:$C$2003, MATCH(B3, ForWeb!$B$2:$B$2003, 0)), "Coming Soon") -> ASUS ExpertBook Ultra | E5: Material Link | F5: =IFERROR(INDEX(ForWeb!$F$2:$F$2003, MATCH(B3, ForWeb!$B$2:$B$2003, 0)), "Coming Soon") -> B9406CAA-THX7312WS - Google Drive
B6: Tagline | C6: =IFERROR(INDEX(ForWeb!$D$2:$D$2003, MATCH(B3, ForWeb!$B$2:$B$2003, 0)), "Coming Soon") -> The Flagship Of The Industry. Period.
B7: KSP | C7: =IFERROR(INDEX(ForWeb!$E$2:$E$2003, MATCH(B3, ForWeb!$B$2:$B$2003, 0)), "Coming Soon") -> - Equiped with a 14-inch 3K tandem OLED Touch screen with up to 1400 nits HDR brightness. - All-metal chassis weighs just up to 0.99 kg, yet delivers 9H durability through Nano Ceramic Technology. - Powered by up to Intel® Core™ Ultra X9 Series 3 processor with Intel® Arc™ graphics, achieving next-level performance.
B8: Title | C8: =IFERROR(INDEX(ForWeb!$H$3:$H$2003, MATCH(B3, ForWeb!$B$3:$B$2003, 0)), "Coming Soon") -> ASUS ExpertBook Ultra (Intel® Core™ Ultra X7 358H/32GB/1TB/Win 11 Home/B9406CAA)
B9: CPU | C9: =IFERROR(INDEX(ForWeb!$I$3:$I$2003, MATCH(B3, ForWeb!$B$3:$B$2003, 0)), "Coming Soon") -> Intel® Core™ Ultra X7 358H 1.9 GHz Intel® AI Boost NPU up to 50 TOPS
B10: GPU | C10: =IFERROR(INDEX(ForWeb!$J$3:$J$2003, MATCH(B3, ForWeb!$B$3:$B$2003, 0)), "Coming Soon") -> Intel® Arc™ Graphics(available for Intel® Core™ Ultra H 5/7/9 with dual channel memory)
B11: OS | C11: =IFERROR(INDEX(ForWeb!$K$3:$K$2003, MATCH(B3, ForWeb!$B$3:$B$2003, 0)), "Coming Soon") -> Windows 11 Home
B12: Panel Size | C12: =IFERROR(INDEX(ForWeb!$M$3:$M$2003, MATCH(B3, ForWeb!$B$3:$B$2003, 0)), "Coming Soon") -> Not Found
B13: Reslolution | C13: =IFERROR(INDEX(ForWeb!$N$3:$N$2003, MATCH(B3, ForWeb!$B$3:$B$2003, 0)), "Coming Soon") -> WQXGA+ (2880 x 1800) 16:10
B14: Brightness | C14: =IFERROR(INDEX(ForWeb!$O$3:$O$2003, MATCH(B3, ForWeb!$B$3:$B$2003, 0)), "Coming Soon") -> 600nits (1400nits HDR peak brightness)
B15: RAM | C15: =IFERROR(INDEX(ForWeb!$P$3:$P$2003, MATCH(B3, ForWeb!$B$3:$B$2003, 0)), "Coming Soon") -> LPDDR5X 32GB
B16: SSD | C16: =IFERROR(INDEX(ForWeb!$Q$3:$Q$2003, MATCH(B3, ForWeb!$B$3:$B$2003, 0)), "Coming Soon") -> 1TB M.2 2280 NVMe™ PCIe® 4.0 SSD
B17: IO Port | C17: =IFERROR(INDEX(ForWeb!$R$3:$R$2003, MATCH(B3, ForWeb!$B$3:$B$2003, 0)), "Coming Soon") -> 2x USB 3.2 Gen 2 Type-A 2x Thunderbolt™ 4, compliant with USB4, support display / power delivery 1x HDMI 2.1 TMDS 1x 3.5mm Combo Audio Jack
B18: Weight (with Battery) | C18: =IFERROR(INDEX(ForWeb!$S$3:$S$2003, MATCH(B3, ForWeb!$B$3:$B$2003, 0)), "Coming Soon") -> 1.10 kg (2.43 lbs)
B19: Size | C19: =IFERROR(INDEX(ForWeb!$T$3:$T$2003, MATCH(B3, ForWeb!$B$3:$B$2003, 0)), "Coming Soon") -> 31.09 x 21.28 x 1.09 ~ 1.64 cm
B20: Expansion Slot | C20: =IFERROR(INDEX(ForWeb!$U$3:$U$2003, MATCH(B3, ForWeb!$B$3:$B$2003, 0)), "Coming Soon") -> 1x M.2 2280 PCIe 4.0x4
B21: Include in the box | C21: =IFERROR(INDEX(ForWeb!$V$3:$V$2003, MATCH(B3, ForWeb!$B$3:$B$2003, 0)), "Coming Soon") -> Sleeve USB3 TO LAN DONGLE
B22: Battery | C22: =IFERROR(INDEX(ForWeb!$W$3:$W$2003, MATCH(B3, ForWeb!$B$3:$B$2003, 0)), "Coming Soon") -> 70WHrs
B23: Power Supply | C23: =IFERROR(INDEX(ForWeb!$X$3:$X$2003, MATCH(B3, ForWeb!$B$3:$B$2003, 0)), "Coming Soon") -> TYPE-C, 90W AC Adapter
B24: Security | C24: =IFERROR(INDEX(ForWeb!$Y$3:$Y$2003, MATCH(B3, ForWeb!$B$3:$B$2003, 0)), "Coming Soon") -> FingerPrint

Sheet Dashboard
Q2: Summary Section | AA2: Incomplete KSP & Link Tracker
Q3: Total Products | T3: =COUNTA('RAW.KSP.LInk'!H3:H1259) -> 393 | U3: =T3/T3 -> 1 | AA3: Missing KSP | AD3: Missing Link
Q4: Total Completed | T4: =COUNTIFS('RAW.KSP.LInk'!E3:E1743,"<>",'RAW.KSP.LInk'!F3:F1743,"<>",'RAW.KSP.LInk'!H3:H1743,"<>") -> 96 | U4: =T4/T3 -> 0.24427481 | AA4: Total Incomplete | AB4: =COUNTIFS('RAW.KSP.LInk'!H3:H756, "<>", 'RAW.KSP.LInk'!E3:E756, "") -> 39 | AD4: Total Incomplete | AE4: =COUNTIFS('RAW.KSP.LInk'!H3:H756, "<>", 'RAW.KSP.LInk'!F3:F756, "") -> 286
Q5: Total Incompleted | T5: =T3-T4 -> 297 | U5: =T5/T3 -> 0.75572519 | AA5: Total Incomplete Rate | AB5: =AB4/T3 -> 0.099236641 | AD5: Total Incomplete Rate | AE5: =AE4/T3 -> 0.72773537
AA6: Missing KSP Product List | AD6: Missing Link Product List
AA8: {=_xlfn._xlws.FILTER('RAW.KSP.LInk'!B3:B1743, ('RAW.KSP.LInk'!E3:E1743 = "") * ('RAW.KSP.LInk'!H3:H1743 <> ""))} -> B1402CBA_ID-NK7850X | AD8: {=_xlfn._xlws.FILTER('RAW.KSP.LInk'!B3:B1743, ('RAW.KSP.LInk'!F3:F1743 = "") * ('RAW.KSP.LInk'!H3:H1743 <> ""))} -> D500SE-380500031W
AA9: EG3408WVAK-BPC385W | AD9: D500SE-382000031W
AA10: EG3408WVAK-BPC585X | AD10: D500SE-382000031X
AA11: EG3408WVAK-BPC515X | AD11: D500SE-385000031W
AA12: EG3408WVAK-BPC785X | AD12: D500SE-385000031X
Q13: Chassis-Type-Level Summary (NX / AIO / PF) | AA13: E1600WKAT-BD182WF | AD13: D500SE-580500033W
Q14: Chassis Type | S14: NX | T14: AIO | U14: PF | AA14: P440VAK-B3851WS | AD14: D500SE-580520033W
Q15: Total Products | S15: =COUNTA('Auto-NX'!A2:A2000) -> 139 | T15: =COUNTA('Auto-AIO'!A2:A2000) -> 163 | U15: =COUNTA('Auto-PF'!A2:A2000) -> 90 | AA15: S501ME-382000013W | AD15: D500SE-585000031W
Q16: Total Completed | S16: {=SUMPRODUCT((LEFT('RAW.KSP.LInk'!H2:H1743,4)="90NX")*('RAW.KSP.LInk'!F2:F1743<>"")*('RAW.KSP.LInk'!E2:E1743<>""))} -> 50 | T16: {=SUMPRODUCT((LEFT('RAW.KSP.LInk'!H2:H1743,4)="90PT")*('RAW.KSP.LInk'!F2:F1743<>"")*('RAW.KSP.LInk'!E2:E1743<>""))} -> 37 | U16: {=SUMPRODUCT((LEFT('RAW.KSP.LInk'!H2:H1743,4)="90PF")*('RAW.KSP.LInk'!F2:F1743<>"")*('RAW.KSP.LInk'!E2:E1743<>""))} -> 9 | AA16: S501ME-385000013W | AD16: D500SE-585000031X
Q17: Total Completion Rate | S17: =S16/S15 -> 0.35971223 | T17: =T16/T15 -> 0.22699387 | U17: =U16/U15 -> 0.1 | AA17: S501ME-585000013W | AD17: D500SE-785000033X
R18: PM Completed | S18: {=SUMPRODUCT((LEFT('RAW.KSP.LInk'!H2:H1743,4)="90NX")*('RAW.KSP.LInk'!E2:E1743<>""))} -> 110 | T18: {=SUMPRODUCT((LEFT('RAW.KSP.LInk'!H2:H1743,4)="90PT")*('RAW.KSP.LInk'!F2:F1743<>""))} -> 41 | U18: {=SUMPRODUCT((LEFT('RAW.KSP.LInk'!H2:H1743,4)="90PF")*('RAW.KSP.LInk'!F2:F1743<>""))} -> 9 | AA18: B5405CCA-NZ5150X | AD18: D500TE-380500033W
R19: PM Completed Rate | S19: =S18/S15 -> 0.79136691 | T19: =T18/T15 -> 0.25153374 | U19: =U18/U15 -> 0.1 | AA19: B5405CVA-NZ5150X | AD19: D500TE-580500035W
R20: PMKT Completed | S20: {=SUMPRODUCT((LEFT('RAW.KSP.LInk'!H2:H1743,4)="90NX")*('RAW.KSP.LInk'!F2:F1743<>""))} -> 57 | T20: {=SUMPRODUCT((LEFT('RAW.KSP.LInk'!H2:H1743,4)="90PT")*('RAW.KSP.LInk'!E2:E1743<>""))} -> 157 | U20: {=SUMPRODUCT((LEFT('RAW.KSP.LInk'!H2:H1743,4)="90PF")*('RAW.KSP.LInk'!E2:E1743<>""))} -> 87 | AA20: B1400CBA-EK7150X | AD20: D500TE-580500035X
R21: PMKT Completed Rate | S21: =S20/S15 -> 0.41007194 | T21: =T20/T15 -> 0.96319018 | U21: =U20/U15 -> 0.96666667 | AA21: B1400CBA-EB5111X | AD21: D500TE-585000032W
AA22: B5402CBA-KI7110X | AD22: D500TE-585000032X
AA23: B1400CBA-EB7111X | AD23: D500TE-780500035W
AA24: B5405CVA-NZ7110X | AD24: D500TE-785000035W
T25: Total Products | U25: 55 | AA25: B5402FBA-HY7110WS | AD25: D500TE-785000035X
T26: Total Completed | U26: 45 | AA26: B1402CBA_ID-NK7850X | AD26: D501SER-385000001W
AA27: B5405CCA-NZ7310X | AD27: D501SER-385000001X
AA28: B5402FBA-HY7110X | AD28: D501SER-585000001W
AA29: B5302FBA-LG7110X | AD29: D501SER-585000001X
AA30: B1400CBA-EK7850X | AD30: D501SER-785000001W
AA31: B1402CBA-NK4149X | AD31: D501SER-785000001X
AA32: B1402CBA-NK5853WS | AD32: DG500MER-715X
AA33: B1402CVA-NK5151X | AD33: S500SE-385000001W
AA34: B3402FBA-EC7150X | AD34: S500SE-585030000W
AA35: B3402FVA-EC7150X | AD35: S500SE-715030000W
AA36: B3402FVA-EC5851WS | AD36: S500TE-3131000300
AA37: B3404CVF-Q55150X | AD37: S500TE-382000002W
AA38: B3404CVA-Q57150X | AD38: S500TE-382000003W
... AA45: CX1405CTA-S65810 | AD45: S500TE-715030002W
AA46: 0 | AD46: S500TE-785000000W
AD47: S500TE-785030002W
AD48: S501MER-385000003W
...

Sheet New Search-Table
B3: BG1408CVA-EB7150X | C3: ⭠Please input the model name e.g. B1402CVA-NK7110X
B5: Product Name | C5: {=IFERROR(TRANSPOSE(_xlfn._xlws.FILTER(ForWeb!B2:D2003,ForWeb!A2:A2003=B3)), "Coming Soon")} -> Coming Soon | E5: Material Link | F5: {=IFERROR(TRANSPOSE(_xlfn._xlws.FILTER(ForWeb!E2:E2003,ForWeb!A2:A2003=B3)), "Coming Soon")} -> Coming Soon
B6: Tagline
B7: KSP
B8: Title | C8: {=IFERROR(TRANSPOSE(_xlfn._xlws.FILTER(ForWeb!G3:W2003,ForWeb!A2:A2003=B3)), "Coming Soon")} -> Coming Soon
B9: CPU
B10: OS
B11: Panel Size
B12: Reslolution
B13: Brightness
B14: GPU
B15: RAM
B16: SSD
B17: IO Port
B18: Weight (with Battery)
B19: Size
B20: Expansion Slot
... B24: Security

Sheet RAW.KSP.LInk
B1: Don't edit. Formula inside. | C1: Don't edit. Formula inside. | D1: Paste by PM | E1: Paste by PM | F1: Paste by PMKT | H1: Paste by PM
A2: Sort Source | B2: Model Name | C2: Marketing Name | D2: Tagline | E2: KSP | F2: Link | H2: Part No <-- Raw data paste from here
A3: =IF(ISBLANK(I3),"",H3) -> 90NX07K1-M00050 | B3: =IF(ISBLANK(I3),"",I3) -> BG1408CVA-EB7150X | C3: =IF(ISBLANK(I3),"",IF(LEFT(H3, 4) = "90PF",_xlfn.XLOOKUP(B3,'Auto-PF'!$A$2:$A$500,'Auto-PF'!$B$2:$B$500,"Not found",0),_xlfn.XLOOKUP(LEFT(B3,5),'MKT name rule'!$B$2:$B$322,'MKT name rule'!$C$2:$C$322, "Not found"))) -> ASUS ExpertBook BG1 | D3: Trusted by IT Experts. Built for Worry-Free Business. | E3: - Dual USB-C (PD/DP) with RJ-45, HDMI, USB-A—one cable powers and displays - Tool-less access to an open SO-DIMM and M.2 slot enables rapid RAM or SSD upgrades - 3-year warranty plus MIL-STD-810H toughness ensure built-in long-term reliability | F3: https://drive.google.com/drive/folders/19BWzD60diPJdw9tDwM4rLliwt4sTsrit?usp=drive_link | H3: 90NX07K1-M00050 | I3: BG1408CVA-EB7150X | J3: VSNX07K1-BU1000 | K3: Intel® Core™ i7-1355U Processor 1.7 GHz (12MB Cache, up to 5.0 GHz, 10 cores, 12 Threads) | L3: DDR4 16GB ( 16GB DDR4 on board ) | M3: 512GB 2280 PCIE G4 SSD | N3: Intel® UHD Graphics | O3: Windows 11 Pro 1-month trial for new Microsoft 365 customers. Credit card required. | P3: M365 FREE TRIAL 30D(WW) | Q3: LCD Cover: Star Black, Plastic Top Case: Star Black, Plastic | R3: 1x DDR4 SO-DIMM slot 1x M.2 2280 PCIe 4.0x4 | S3: Front: 720p HD camera Rear: - With privacy shutter World-Facing: - | T3: Audio by Dirac Built-in speaker | U3: Wi-Fi 6(802.11ax) (Dual band) 2*2 + Bluetooth® 5.2 Wireless Card | V3: 1x USB 2.0 Type-A 1x USB 3.2 Gen 1 Type-A 1x USB 3.2 Gen 1 Type-C support power delivery 1x USB 3.2 Gen 2 Type-C support display / power delivery 1x HDMI 1.4, up to 1920x1080p/60Hz 1x 3.5mm Combo Audio Jack 1x RJ45 Gigabit Ethernet | W3: FingerPrint BIOS Booting User Password Protection BIOS setup user password HDD User Password Protection and Security Support Absolute Persistence 2.0 (Computrace) Trusted Platform Module (TPM) 2.0 Fingerprint sensor intergrated with Touchpad Kensington Nano Security Slot™(6x 2.5mm) | X3: Backpack Carry bag USB-C to USB-C cable | Y3: 14.0 | Z3: LED Back-lit-Narrow border | AA3: 250nits | AB3: FHD 1920X1080 16:9 | AC3: Anti-Glare | AD3: NTSC:45% | AE3: non-Touch | AF3: Wide View | AG3: ID,1Y CARRY-IN(ADP)+2Y CARRY-IN | AH3: 1.469 Kg | AI3: 1.305 | AJ3: 32.69 x 21.45 x 1.99 ~ 1.99 cm (12.87" x 8.44" x 0.78" ~ 0.78") | AK3: 42WHrs, 3S1P, 3-cell Li-ion | AL3: TYPE-C, 65W AC Adapter, Output: 20V DC, 3.25A, 65W, Input: 100~240V AC 50/60Hz universal | AN3: N/A | AO3: Backlit Chiclet Keyboard | AP3: W/FINGERPRINT | AQ3: EPEAT Gold Energy star 8.0 FSC Mix TCO Certified RoHS REACH | AR3: US MIL-STD 810H military-grade standard | AT3: LED Backlit
A4: =IF(ISBLANK(I4),"",H4) -> 90NX08Z1-M000S0 | B4: =IF(ISBLANK(I4),"",I4) -> BG1409CVA-S63850W | C4: =IF(ISBLANK(I4),"",IF(LEFT(H4, 4) = "90PF",_xlfn.XLOOKUP(B4,'Auto-PF'!$A$2:$A$500,'Auto-PF'!$B$2:$B$500,"Not found",0),_xlfn.XLOOKUP(LEFT(B4,5),'MKT name rule'!$B$2:$B$322,'MKT name rule'!$C$2:$C$322, "Not found"))) -> ASUS ExpertBook BG1 | D4: Trusted by IT Experts. Built for Worry-Free Business. | E4: - Dual USB-C (PD/DP) with RJ-45, HDMI, USB-A—one cable powers and displays - Tool-less access to an open SO-DIMM and M.2 slot enables rapid RAM or SSD upgrades - 3-year warranty plus MIL-STD-810H toughness ensure built-in long-term reliability | F4: https://drive.google.com/drive/folders/1d5knYxQIEJULaPttrlz6id8RJMjrJBwn?usp=drive_link | H4: 90NX08Z1-M000S0 | I4: BG1409CVA-S63850W | J4: VSNX08Z1-BU2000 | K4: Intel® Core™ i3-1315U Processor 1.2 GHz (10MB Cache, up to 4.5 GHz, 6 cores, 8 Threads) | L4: DDR5 8GB ( 8GB DDR5 SO-DIMM ) | M4: 512GB 2280 PCIE G4 SSD | N4: Intel® UHD Graphics | O4: Windows 11 Home - ASUS recommends Windows 11 Pro for business 1-month trial for new Microsoft 365 customers. Credit card required. | P4: M365 FREE TRIAL 30D(WW) | Q4: LCD Cover: Gentle Grey, Plastic Top Case: Gentle Grey, Plastic | R4: 2x DDR5 SO-DIMM slots 1x M.2 2230 PCIe 4.0x4 1x M.2 2280 PCIe 4.0x4 | S4: Front: 720p HD camera Rear: - With privacy shutter World-Facing: - | T4: Audio by Dirac Built-in speaker Built-in array microphone | U4: Wi-Fi 6E(802.11ax) (Dual band) 2*2 + Bluetooth® 5.4 Wireless Card | V4: 2x USB 3.2 Gen 1 Type-A 2x USB 3.2 Gen 2 Type-C support display / power delivery 1x HDMI 1.4 1x 3.5mm Combo Audio Jack 1x RJ45 Gigabit Ethernet | W4: FingerPrint BIOS Booting User Password Protection BIOS setup user password HDD User Password Protection and Security Support Absolute Persistence 2.0 (Computrace) Trusted Platform Module (TPM) 2.0 Fingerprint sensor intergrated with Touchpad Kensington Nano Security Slot™(6x 2.5mm) | X4: Backpack Carry bag USB-C to USB-C cable | Y4: 14.0 | Z4: LED Back-lit-Narrow border | AA4: 300nits | AB4: FHD 1920X1080 16:9 | AC4: Anti-Glare | AD4: NTSC:45% | AE4: non-Touch | AF4: Wide View | AG4: ID,1Y CARRY-IN(ADP)+2Y CARRY-IN | AH4: 1.4 Kg | AI4: 1.215 | AJ4: 32.45 x 21.44 x 1.97 ~ 1.97 cm (12.78" x 8.44" x 0.78" ~ 0.78") | AK4: 42WHrs, 3S1P, 3-cell Li-ion | AL4: TYPE-C, 65W AC Adapter, Output: 20V DC, 3.25A, 65W, Input: 100~240V AC 50/60Hz universal | AN4: N/A | AO4: Backlit Chiclet Keyboard | AP4: W/FINGERPRINT | AQ4: Energy star 8.0 FSC Mix TCO Certified RoHS REACH | AR4: US MIL-STD 810H military-grade standard | AT4: LED Backlit
A5: =IF(ISBLANK(I5),"",H5) -> 90NX08Z1-M001L0 | B5: =IF(ISBLANK(I5),"",I5) -> BG1409CVA-S67110W | C5: =IF(ISBLANK(I5),"",IF(LEFT(H5, 4) = "90PF",_xlfn.XLOOKUP(B5,'Auto-PF'!$A$2:$A$500,'Auto-PF'!$B$2:$B$500,"Not found",0),_xlfn.XLOOKUP(LEFT(B5,5),'MKT name rule'!$B$2:$B$322,'MKT name rule'!$C$2:$C$322, "Not found"))) -> ASUS ExpertBook BG1 | D5: Trusted by IT Experts. Built for Worry-Free Business. | E5: - Dual USB-C (PD/DP) with RJ-45, HDMI, USB-A—one cable powers and displays - Tool-less access to an open SO-DIMM and M.2 slot enables rapid RAM or SSD upgrades - 3-year warranty plus MIL-STD-810H toughness ensure built-in long-term reliability | F5: https://drive.google.com/drive/folders/1_P9IebbgA0f5l1zXB4UwO2nMqKsKzT7p?usp=drive_link | H5: 90NX08Z1-M001L0 | I5: BG1409CVA-S67110W | J5: VSNX08Z1-BU2000 | K5: Intel® Core™ i7-1355U Processor 1.7 GHz (12MB Cache, up to 5.0 GHz, 10 cores, 12 Threads) | L5: DDR5 16GB ( 8GB DDR5 SO-DIMM *2 ) | M5: 1TB 2280 PCIE G4 SSD | N5: Intel Iris Xᵉ Graphics (available for Intel® Core™ i5/i7/i9 with dual channel memory) | O5: Windows 11 Home - ASUS recommends Windows 11 Pro for business 1-month trial for new Microsoft 365 customers. Credit card required. | P5: M365 FREE TRIAL 30D(WW) | Q5: LCD Cover: Gentle Grey, Plastic Top Case: Gentle Grey, Plastic | R5: 2x DDR5 SO-DIMM slots 1x M.2 2230 PCIe 4.0x4 1x M.2 2280 PCIe 4.0x4 | S5: Front: 720p HD camera Rear: - With privacy shutter World-Facing: - | T5: Audio by Dirac Built-in speaker Built-in array microphone | U5: Wi-Fi 6E(802.11ax) (Dual band) 2*2 + Bluetooth® 5.4 Wireless Card | V5: 2x USB 3.2 Gen 1 Type-A 2x USB 3.2 Gen 2 Type-C support display / power delivery 1x HDMI 1.4 1x 3.5mm Combo Audio Jack 1x RJ45 Gigabit Ethernet | W5: FingerPrint BIOS Booting User Password Protection BIOS setup user password HDD User Password Protection and Security Support Absolute Persistence 2.0 (Computrace) Trusted Platform Module (TPM) 2.0 Fingerprint sensor intergrated with Touchpad Kensington Nano Security Slot™(6x 2.5mm) | X5: Backpack Carry bag USB-C to USB-C cable | Y5: 14.0 | Z5: LED Back-lit-Narrow border | AA5: 300nits | AB5: FHD 1920X1080 16:9 | AC5: Anti-Glare | AD5: NTSC:45% | AE5: non-Touch | AF5: Wide View | AG5: ID,1Y CARRY-IN(ADP)+2Y CARRY-IN | AH5: 1.407 Kg | AI5: 1.215 | AJ5: 32.45 x 21.44 x 1.97 ~ 1.97 cm (12.78" x 8.44" x 0.78" ~ 0.78") | AK5: 50WHrs, 3S1P, 3-cell Li-ion | AL5: TYPE-C, 65W AC Adapter, Output: 20V DC, 3.25A, 65W, Input: 100~240V AC 50/60Hz universal | AN5: N/A | AO5: Backlit Chiclet Keyboard | AP5: W/FINGERPRINT | AQ5: Energy star 8.0 FSC Mix TCO Certified RoHS REACH | AR5: US MIL-STD 810H military-grade standard | AT5: LED Backlit
A6: =IF(ISBLANK(I6),"",H6) -> 90NX08Z1-M001A0 | B6: =IF(ISBLANK(I6),"",I6) -> BG1409CVA-S65150W | C6: =IF(ISBLANK(I6),"",IF(LEFT(H6, 4) = "90PF",_xlfn.XLOOKUP(B6,'Auto-PF'!$A$2:$A$500,'Auto-PF'!$B$2:$B$500,"Not found",0),_xlfn.XLOOKUP(LEFT(B6,5),'MKT name rule'!$B$2:$B$322,'MKT name rule'!$C$2:$C$322, "Not found"))) -> ASUS ExpertBook BG1 | D6: Trusted by IT Experts. Built for Worry-Free Business. | E6: - Dual USB-C (PD/DP) with RJ-45, HDMI, USB-A—one cable powers and displays - Tool-less access to an open SO-DIMM and M.2 slot enables rapid RAM or SSD upgrades - 3-year warranty plus MIL-STD-810H toughness ensure built-in long-term reliability | F6: https://drive.google.com/drive/folders/1JX6Mhv1vf949Z1JaZkF5bjPFcmjhJqrL?usp=drive_link | H6: 90NX08Z1-M001A0 | I6: BG1409CVA-S65150W | J6: VSNX08Z1-BU2000 | K6: Intel® Core™ i5-1334U Processor 1.3 GHz (12MB Cache, up to 4.6 GHz, 10 cores, 12 Threads) | L6: DDR5 16GB ( 8GB DDR5 SO-DIMM *2 ) | M6: 512GB 2280 PCIE G4 SSD | N6: Intel Iris Xᵉ Graphics (available for Intel® Core™ i5/i7/i9 with dual channel memory) | O6: Windows 11 Home - ASUS recommends Windows 11 Pro for business 1-month trial for new Microsoft 365 customers. Credit card required. | P6: M365 FREE TRIAL 30D(WW) | Q6: LCD Cover: Gentle Grey, Plastic Top Case: Gentle Grey, Plastic | R6: 2x DDR5 SO-DIMM slots 1x M.2 2230 PCIe 4.0x4 1x M.2 2280 PCIe 4.0x4 | S6: Front: 720p HD camera Rear: - With privacy shutter World-Facing: - | T6: Audio by Dirac Built-in speaker Built-in array microphone | U6: Wi-Fi 6E(802.11ax) (Dual band) 2*2 + Bluetooth® 5.4 Wireless Card | V6: 2x USB 3.2 Gen 1 Type-A 2x USB 3.2 Gen 2 Type-C support display / power delivery 1x HDMI 1.4 1x 3.5mm Combo Audio Jack 1x RJ45 Gigabit Ethernet | W6: FingerPrint BIOS Booting User Password Protection BIOS setup user password HDD User Password Protection and Security Support Absolute Persistence 2.0 (Computrace) Trusted Platform Module (TPM) 2.0 Fingerprint sensor intergrated with Touchpad Kensington Nano Security Slot™(6x 2.5mm) | X6: Backpack Carry bag USB-C to USB-C cable | Y6: 14.0 | Z6: LED Back-lit-Narrow border | AA6: 300nits | AB6: FHD 1920X1080 16:9 | AC6: Anti-Glare | AD6: NTSC:45% | AE6: non-Touch | AF6: Wide View | AG6: ID,1Y CARRY-IN(ADP)+2Y CARRY-IN | AH6: 1.407 Kg | AI6: 1.215 | AJ6: 32.45 x 21.44 x 1.97 ~ 1.97 cm (12.78" x 8.44" x 0.78" ~ 0.78") | AK6: 50WHrs, 3S1P, 3-cell Li-ion | AL6: TYPE-C, 65W AC Adapter, Output: 20V DC, 3.25A, 65W, Input: 100~240V AC 50/60Hz universal | AN6: N/A | AO6: Backlit Chiclet Keyboard | AP6: W/FINGERPRINT | AQ6: Energy star 8.0 FSC Mix TCO Certified RoHS REACH | AR6: US MIL-STD 810H military-grade standard | AT6: LED Backlit
A7: =IF(ISBLANK(I7),"",H7) -> 90NX08Z1-M00180 | B7: =IF(ISBLANK(I7),"",I7) -> BG1409CVA-S65850W | C7: =IF(ISBLANK(I7),"",IF(LEFT(H7, 4) = "90PF",_xlfn.XLOOKUP(B7,'Auto-PF'!$A$2:$A$500,'Auto-PF'!$B$2:$B$500,"Not found",0),_xlfn.XLOOKUP(LEFT(B7,5),'MKT name rule'!$B$2:$B$322,'MKT name rule'!$C$2:$C$322, "Not found"))) -> ASUS ExpertBook BG1 | D7: Trusted by IT Experts. Built for Worry-Free Business. | E7: - Dual USB-C (PD/DP) with RJ-45, HDMI, USB-A—one cable powers and displays - Tool-less access to an open SO-DIMM and M.2 slot enables rapid RAM or SSD upgrades - 3-year warranty plus MIL-STD-810H toughness ensure built-in long-term reliability | F7: https://drive.google.com/drive/folders/17w243qOUfVGBUWsv7ctQeYEmSAClm8xx?usp=drive_link | H7: 90NX08Z1-M00180 | I7: BG1409CVA-S65850W | J7: VSNX08Z1-BU2000 | K7: Intel® Core™ i5-1334U Processor 1.3 GHz (12MB Cache, up to 4.6 GHz, 10 cores, 12 Threads) | L7: DDR5 8GB ( 8GB DDR5 SO-DIMM ) | M7: 512GB 2280 PCIE G4 SSD | N7: Intel® UHD Graphics | O7: Windows 11 Home - ASUS recommends Windows 11 Pro for business 1-month trial for new Microsoft 365 customers. Credit card required. | P7: M365 FREE TRIAL 30D(WW) | Q7: LCD Cover: Gentle Grey, Plastic Top Case: Gentle Grey, Plastic | R7: 2x DDR5 SO-DIMM slots 1x M.2 2230 PCIe 4.0x4 1x M.2 2280 PCIe 4.0x4 | S7: Front: 720p HD camera Rear: - With privacy shutter World-Facing: - | T7: Audio by Dirac Built-in speaker Built-in array microphone | U7: Wi-Fi 6E(802.11ax) (Dual band) 2*2 + Bluetooth® 5.4 Wireless Card | V7: 2x USB 3.2 Gen 1 Type-A 2x USB 3.2 Gen 2 Type-C support display / power delivery 1x HDMI 1.4 1x 3.5mm Combo Audio Jack 1x RJ45 Gigabit Ethernet | W7: FingerPrint BIOS Booting User Password Protection BIOS setup user password HDD User Password Protection and Security Support Absolute Persistence 2.0 (Computrace) Trusted Platform Module (TPM) 2.0 Fingerprint sensor intergrated with Touchpad Kensington Nano Security Slot™(6x 2.5mm) | X7: Backpack Carry bag USB-C to USB-C cable | Y7: 14.0 | Z7: LED Back-lit-Narrow border | AA7: 300nits | AB7: FHD 1920X1080 16:9 | AC7: Anti-Glare | AD7: NTSC:45% | AE7: non-Touch | AF7: Wide View | AG7: ID,1Y CARRY-IN(ADP)+2Y CARRY-IN | AH7: 1.407 Kg | AI7: 1.215 | AJ7: 32.45 x 21.44 x 1.97 ~ 1.97 cm (12.78" x 8.44" x 0.78" ~ 0.78") | AK7: 50WHrs, 3S1P, 3-cell Li-ion | AL7: TYPE-C, 65W AC Adapter, Output: 20V DC, 3.25A, 65W, Input: 100~240V AC 50/60Hz universal | AN7: N/A | AO7: Backlit Chiclet Keyboard | AP7: W/FINGERPRINT | AQ7: Energy star 8.0 FSC Mix TCO Certified RoHS REACH | AR7: US MIL-STD 810H military-grade standard | AT7: LED Backlit
A8: =IF(ISBLANK(I8),"",H8) -> 90NX07K1-M000J0 | B8: =IF(ISBLANK(I8),"",I8) -> BG1408CVA-EB7150X | C8: =IF(ISBLANK(I8),"",IF(LEFT(H8, 4) = "90PF",_xlfn.XLOOKUP(B8,'Auto-PF'!$A$2:$A$500,'Auto-PF'!$B$2:$B$500,"Not found",0),_xlfn.XLOOKUP(LEFT(B8,5),'MKT name rule'!$B$2:$B$322,'MKT name rule'!$C$2:$C$322, "Not found"))) -> ASUS ExpertBook BG1 | D8: Trusted by IT Experts. Built for Worry-Free Business. | E8: - Dual USB-C (PD/DP) with RJ-45, HDMI, USB-A—one cable powers and displays - Tool-less access to an open SO-DIMM and M.2 slot enables rapid RAM or SSD upgrades - 3-year warranty plus MIL-STD-810H toughness ensure built-in long-term reliability | F8: https://drive.google.com/drive/folders/19BWzD60diPJdw9tDwM4rLliwt4sTsrit?usp=drive_link | H8: 90NX07K1-M000J0 | I8: BG1408CVA-EB7150X | J8: VSNX07K1-BU1000 | K8: Intel® Core™ i7-1355U Processor 1.7 GHz (12MB Cache, up to 5.0 GHz, 10 cores, 12 Threads) | L8: DDR4 16GB ( 8GB DDR4 on board + 8GB DDR4 SO-DIMM ) | M8: 512GB 2280 PCIE G4 SSD | N8: Intel Iris Xᵉ Graphics (available for Intel® Core™ i5/i7/i9 with dual channel memory) | O8: Windows 11 Pro 1-month trial for new Microsoft 365 customers. Credit card required. | P8: M365 FREE TRIAL 30D(WW) | Q8: LCD Cover: Star Black, Plastic Top Case: Star Black, Plastic | R8: 1x DDR4 SO-DIMM slot 1x M.2 2280 PCIe 4.0x4 | S8: Front: 720p HD camera Rear: - With privacy shutter World-Facing: - | T8: Audio by Dirac Built-in speaker | U8: Wi-Fi 6(802.11ax) (Dual band) 2*2 + Bluetooth® 5.2 Wireless Card | V8: 1x USB 2.0 Type-A 1x USB 3.2 Gen 1 Type-A 1x USB 3.2 Gen 1 Type-C support power delivery 1x USB 3.2 Gen 2 Type-C support display / power delivery 1x HDMI 1.4, up to 1920x1080p/60Hz 1x 3.5mm Combo Audio Jack 1x RJ45 Gigabit Ethernet | W8: FingerPrint BIOS Booting User Password Protection BIOS setup user password HDD User Password Protection and Security Support Absolute Persistence 2.0 (Computrace) Trusted Platform Module (TPM) 2.0 Fingerprint sensor intergrated with Touchpad Kensington Nano Security Slot™(6x 2.5mm) | X8: Backpack Carry bag USB-C to USB-C cable | Y8: 14.0 | Z8: LED Back-lit-Narrow border | AA8: 250nits | AB8: FHD 1920X1080 16:9 | AC8: Anti-Glare | AD8: NTSC:45% | AE8: non-Touch | AF8: Wide View | AG8: ID,1Y CARRY-IN(ADP)+2Y CARRY-IN | AH8: 1.469 Kg | AI8: 1.305 | AJ8: 32.69 x 21.45 x 1.99 ~ 1.99 cm (12.87" x 8.44" x 0.78" ~ 0.78") | AK8: 42WHrs, 3S1P, 3-cell Li-ion | AL8: TYPE-C, 65W AC Adapter, Output: 20V DC, 3.25A, 65W, Input: 100~240V AC 50/60Hz universal | AN8: N/A | AO8: Backlit Chiclet Keyboard | AP8: W/FINGERPRINT | AQ8: EPEAT Gold Energy star 8.0 FSC Mix TCO Certified RoHS REACH | AR8: US MIL-STD 810H military-grade standard | AT8: LED Backlit
A9: =IF(ISBLANK(I9),"",H9) -> 90NX08Z1-M001F0 | B9: =IF(ISBLANK(I9),"",I9) -> BG1409CVA-S67150W | C9: =IF(ISBLANK(I9),"",IF(LEFT(H9, 4) = "90PF",_xlfn.XLOOKUP(B9,'Auto-PF'!$A$2:$A$500,'Auto-PF'!$B$2:$B$500,"Not found",0),_xlfn.XLOOKUP(LEFT(B9,5),'MKT name rule'!$B$2:$B$322,'MKT name rule'!$C$2:$C$322, "Not found"))) -> ASUS ExpertBook BG1 | D9: Trusted by IT Experts. Built for Worry-Free Business. | E9: - Dual USB-C (PD/DP) with RJ-45, HDMI, USB-A—one cable powers and displays - Tool-less access to an open SO-DIMM and M.2 slot enables rapid RAM or SSD upgrades - 3-year warranty plus MIL-STD-810H toughness ensure built-in long-term reliability | F9: https://drive.google.com/drive/folders/16X1B5EeAnauCyYnjnSp9MSbljj26xL5I?usp=drive_link | H9: 90NX08Z1-M001F0 | I9: BG1409CVA-S67150W | J9: VSNX08Z1-BU2000 | K9: Intel® Core™ i7-1355U Processor 1.7 GHz (12MB Cache, up to 5.0 GHz, 10 cores, 12 Threads) | L9: DDR5 16GB ( 8GB DDR5 SO-DIMM *2 ) | M9: 512GB 2280 PCIE G4 SSD | N9: Intel Iris Xᵉ Graphics (available for Intel® Core™ i5/i7/i9 with dual channel memory) | O9: Windows 11 Home - ASUS recommends Windows 11 Pro for business 1-month trial for new Microsoft 365 customers. Credit card required. | P9: M365 FREE TRIAL 30D(WW) | Q9: LCD Cover: Gentle Grey, Plastic Top Case: Gentle Grey, Plastic | R9: 2x DDR5 SO-DIMM slots 1x M.2 2230 PCIe 4.0x4 1x M.2 2280 PCIe 4.0x4 | S9: Front: 720p HD camera Rear: - With privacy shutter World-Facing: - | T9: Audio by Dirac Built-in speaker Built-in array microphone | U9: Wi-Fi 6E(802.11ax) (Dual band) 2*2 + Bluetooth® 5.4 Wireless Card | V9: 2x USB 3.2 Gen 1 Type-A 2x USB 3.2 Gen 2 Type-C support display / power delivery 1x HDMI 1.4 1x 3.5mm Combo Audio Jack 1x RJ45 Gigabit Ethernet | W9: FingerPrint BIOS Booting User Password Protection BIOS setup user password HDD User Password Protection and Security Support Absolute Persistence 2.0 (Computrace) Trusted Platform Module (TPM) 2.0 Fingerprint sensor intergrated with Touchpad Kensington Nano Security Slot™(6x 2.5mm) | X9: Backpack Carry bag USB-C to USB-C cable | Y9: 14.0 | Z9: LED Back-lit-Narrow border | AA9: 300nits | AB9: FHD 1920X1080 16:9 | AC9: Anti-Glare | AD9: NTSC:45% | AE9: non-Touch | AF9: Wide View | AG9: ID,1Y CARRY-IN(ADP)+2Y CARRY-IN | AH9: 1.407 Kg | AI9: 1.215 | AJ9: 32.45 x 21.44 x 1.97 ~ 1.97 cm (12.78" x 8.44" x 0.78" ~ 0.78") | AK9: 50WHrs, 3S1P, 3-cell Li-ion | AL9: TYPE-C, 65W AC Adapter, Output: 20V DC, 3.25A, 65W, Input: 100~240V AC 50/60Hz universal | AN9: N/A | AO9: Backlit Chiclet Keyboard | AP9: W/FINGERPRINT | AQ9: Energy star 8.0 FSC Mix TCO Certified RoHS REACH | AR9: US MIL-STD 810H military-grade standard | AT9: LED Backlit
A10: =IF(ISBLANK(I10),"",H10) -> 90NX08Z1-M001M0 | B10: =IF(ISBLANK(I10),"",I10) -> BG1409CVA-S67110X | C10: =IF(ISBLANK(I10),"",IF(LEFT(H10, 4) = "90PF",_xlfn.XLOOKUP(B10,'Auto-PF'!$A$2:$A$500,'Auto-PF'!$B$2:$B$500,"Not found",0),_xlfn.XLOOKUP(LEFT(B10,5),'MKT name rule'!$B$2:$B$322,'MKT name rule'!$C$2:$C$322, "Not found"))) -> ASUS ExpertBook BG1 | D10: Trusted by IT Experts. Built for Worry-Free Business. | E10: - Dual USB-C (PD/DP) with RJ-45, HDMI, USB-A—one cable powers and displays - Tool-less access to an open SO-DIMM and M.2 slot enables rapid RAM or SSD upgrades - 3-year warranty plus MIL-STD-810H toughness ensure built-in long-term reliability | F10: https://drive.google.com/drive/folders/1VEgk1dU8LZ4NJp_8njiV72udvFp8RmNj?usp=drive_link | H10: 90NX08Z1-M001M0 | I10: BG1409CVA-S67110X | J10: VSNX08Z1-BU2000 | K10: Intel® Core™ i7-1355U Processor 1.7 GHz (12MB Cache, up to 5.0 GHz, 10 cores, 12 Threads) | L10: DDR5 16GB ( 8GB DDR5 SO-DIMM *2 ) | M10: 1TB 2280 PCIE G4 SSD | N10: Intel Iris Xᵉ Graphics (available for Intel® Core™ i5/i7/i9 with dual channel memory) | O10: Windows 11 Pro 1-month trial for new Microsoft 365 customers. Credit card required. | P10: M365 FREE TRIAL 30D(WW) | Q10: LCD Cover: Gentle Grey, Plastic Top Case: Gentle Grey, Plastic | R10: 2x DDR5 SO-DIMM slots 1x M.2 2230 PCIe 4.0x4 1x M.2 2280 PCIe 4.0x4 | S10: Front: 720p HD camera Rear: - With privacy shutter World-Facing: - | T10: Audio by Dirac Built-in speaker Built-in array microphone | U10: Wi-Fi 6E(802.11ax) (Dual band) 2*2 + Bluetooth® 5.4 Wireless Card | V10: 2x USB 3.2 Gen 1 Type-A 2x USB 3.2 Gen 2 Type-C support display / power delivery 1x HDMI 1.4 1x 3.5mm Combo Audio Jack 1x RJ45 Gigabit Ethernet | W10: FingerPrint BIOS Booting User Password Protection BIOS setup user password HDD User Password Protection and Security Support Absolute Persistence 2.0 (Computrace) Trusted Platform Module (TPM) 2.0 Fingerprint sensor intergrated with Touchpad Kensington Nano Security Slot™(6x 2.5mm) | X10: Backpack Carry bag USB-C to USB-C cable | Y10: 14.0 | Z10: LED Back-lit-Narrow border | AA10: 300nits | AB10: FHD 1920X1080 16:9 | AC10: Anti-Glare | AD10: NTSC:45% | AE10: non-Touch | AF10: Wide View | AG10: ID,1Y CARRY-IN(ADP)+2Y CARRY-IN | AH10: 1.407 Kg | AI10: 1.215 | AJ10: 32.45 x 21.44 x 1.97 ~ 1.97 cm (12.78" x 8.44" x 0.78" ~ 0.78") | AK10: 50WHrs, 3S1P, 3-cell Li-ion | AL10: TYPE-C, 65W AC Adapter, Output: 20V DC, 3.25A, 65W, Input: 100~240V AC 50/60Hz universal | AN10: N/A | AO10: Backlit Chiclet Keyboard | AP10: W/FINGERPRINT | AQ10: Energy star 8.0 FSC Mix TCO Certified RoHS REACH | AR10: US MIL-STD 810H military-grade standard | AT10: LED Backlit
A11: =IF(ISBLANK(I11),"",H11) -> 90NX08Z1-M00190 | B11: =IF(ISBLANK(I11),"",I11) -> BG1409CVA-S65850X | C11: =IF(ISBLANK(I11),"",IF(LEFT(H11, 4) = "90PF",_xlfn.XLOOKUP(B11,'Auto-PF'!$A$2:$A$500,'Auto-PF'!$B$2:$B$500,"Not found",0),_xlfn.XLOOKUP(LEFT(B11,5),'MKT name rule'!$B$2:$B$322,'MKT name rule'!$C$2:$C$322, "Not found"))) -> ASUS ExpertBook BG1 | D11: Trusted by IT Experts. Built for Worry-Free Business. | E11: - Dual USB-C (PD/DP) with RJ-45, HDMI, USB-A—one cable powers and displays - Tool-less access to an open SO-DIMM and M.2 slot enables rapid RAM or SSD upgrades - 3-year warranty plus MIL-STD-810H toughness ensure built-in long-term reliability | F11: https://drive.google.com/drive/folders/1mU1n5uXIV4ZbtbPgCj5Geo7z1z78qz6Y?usp=drive_link | H11: 90NX08Z1-M00190 | I11: BG1409CVA-S65850X | J11: VSNX08Z1-BU2000 | K11: Intel® Core™ i5-1334U Processor 1.3 GHz (12MB Cache, up to 4.6 GHz, 10 cores, 12 Threads) | L11: DDR5 8GB ( 8GB DDR5 SO-DIMM ) | M11: 512GB 2280 PCIE G4 SSD | N11: Intel® UHD Graphics | O11: Windows 11 Pro 1-month trial for new Microsoft 365 customers. Credit card required. | P11: M365 FREE TRIAL 30D(WW) | Q11: LCD Cover: Gentle Grey, Plastic Top Case: Gentle Grey, Plastic | R11: 2x DDR5 SO-DIMM slots 1x M.2 2230 PCIe 4.0x4 1x M.2 2280 PCIe 4.0x4 | S11: Front: 720p HD camera Rear: - With privacy shutter World-Facing: - | T11: Audio by Dirac Built-in speaker Built-in array microphone | U11: Wi-Fi 6E(802.11ax) (Dual band) 2*2 + Bluetooth® 5.4 Wireless Card | V11: 2x USB 3.2 Gen 1 Type-A 2x USB 3.2 Gen 2 Type-C support display / power delivery 1x HDMI 1.4 1x 3.5mm Combo Audio Jack 1x RJ45 Gigabit Ethernet | W11: FingerPrint BIOS Booting User Password Protection BIOS setup user password HDD User Password Protection and Security Support Absolute Persistence 2.0 (Computrace) Trusted Platform Module (TPM) 2.0 Fingerprint sensor intergrated with Touchpad Kensington Nano Security Slot™(6x 2.5mm) | X11: Backpack Carry bag USB-C to USB-C cable | Y11: 14.0 | Z11: LED Back-lit-Narrow border | AA11: 300nits | AB11: FHD 1920X1080 16:9 | AC11: Anti-Glare | AD11: NTSC:45% | AE11: non-Touch | AF11: Wide View | AG11: ID,1Y CARRY-IN(ADP)+2Y CARRY-IN | AH11: 1.407 Kg | AI11: 1.215 | AJ11: 32.45 x 21.44 x 1.97 ~ 1.97 cm (12.78" x 8.44" x 0.78" ~ 0.78") | AK11: 50WHrs, 3S1P, 3-cell Li-ion | AL11: TYPE-C, 65W AC Adapter, Output: 20V DC, 3.25A, 65W, Input: 100~240V AC 50/60Hz universal | AN11: N/A | AO11: Backlit Chiclet Keyboard | AP11: W/FINGERPRINT | AQ11: Energy star 8.0 FSC Mix TCO Certified RoHS REACH | AR11: US MIL-STD 810H military-grade standard | AT11: LED Backlit
A12: =IF(ISBLANK(I12),"",H12) -> 90NX08Z1-M001D0 | B12: =IF(ISBLANK(I12),"",I12) -> BG1409CVA-S67850W | C12: =IF(ISBLANK(I12),"",IF(LEFT(H12, 4) = "90PF",_xlfn.XLOOKUP(B12,'Auto-PF'!$A$2:$A$500,'Auto-PF'!$B$2:$B$500,"Not found",0),_xlfn.XLOOKUP(LEFT(B12,5),'MKT name rule'!$B$2:$B$322,'MKT name rule'!$C$2:$C$322, "Not found"))) -> ASUS ExpertBook BG1 | D12: Trusted by IT Experts. Built for Worry-Free Business. | E12: - Dual USB-C (PD/DP) with RJ-45, HDMI, USB-A—one cable powers and displays - Tool-less access to an open SO-DIMM and M.2 slot enables rapid RAM or SSD upgrades - 3-year warranty plus MIL-STD-810H toughness ensure built-in long-term reliability | F12: https://drive.google.com/drive/folders/1doOTPtdIYhxgXrNArRsRrGOx_SanXYtN?usp=drive_link | H12: 90NX08Z1-M001D0 | I12: BG1409CVA-S67850W | J12: VSNX08Z1-BU2000 | K12: Intel® Core™ i7-1355U Processor 1.7 GHz (12MB Cache, up to 5.0 GHz, 10 cores, 12 Threads) | L12: DDR5 8GB ( 8GB DDR5 SO-DIMM ) | M12: 512GB 2280 PCIE G4 SSD | N12: Intel® UHD Graphics | O12: Windows 11 Home - ASUS recommends Windows 11 Pro for business 1-month trial for new Microsoft 365 customers. Credit card required. | P12: M365 FREE TRIAL 30D(WW) | Q12: LCD Cover: Gentle Grey, Plastic Top Case: Gentle Grey, Plastic | R12: 2x DDR5 SO-DIMM slots 1x M.2 2230 PCIe 4.0x4 1x M.2 2280 PCIe 4.0x4 | S12: Front: 720p HD camera Rear: - With privacy shutter World-Facing: - | T12: Audio by Dirac Built-in speaker Built-in array microphone | U12: Wi-Fi 6E(802.11ax) (Dual band) 2*2 + Bluetooth® 5.4 Wireless Card | V12: 2x USB 3.2 Gen 1 Type-A 2x USB 3.2 Gen 2 Type-C support display / power delivery 1x HDMI 1.4 1x 3.5mm Combo Audio Jack 1x RJ45 Gigabit Ethernet | W12: FingerPrint BIOS Booting User Password Protection BIOS setup user password HDD User Password Protection and Security Support Absolute Persistence 2.0 (Computrace) Trusted Platform Module (TPM) 2.0 Fingerprint sensor intergrated with Touchpad Kensington Nano Security Slot™(6x 2.5mm) | X12: Backpack Carry bag USB-C to USB-C cable | Y12: 14.0 | Z12: LED Back-lit-Narrow border | AA12: 300nits | AB12: FHD 1920X1080 16:9 | AC12: Anti-Glare | AD12: NTSC:45% | AE12: non-Touch | AF12: Wide View | AG12: ID,1Y CARRY-IN(ADP)+2Y CARRY-IN | AH12: 1.407 Kg | AI12: 1.215 | AJ12: 32.45 x 21.44 x 1.97 ~ 1.97 cm (12.78" x 8.44" x 0.78" ~ 0.78") | AK12: 50WHrs, 3S1P, 3-cell Li-ion | AL12: TYPE-C, 65W AC Adapter, Output: 20V DC, 3.25A, 65W, Input: 100~240V AC 50/60Hz universal | AN12: N/A | AO12: Backlit Chiclet Keyboard | AP12: W/FINGERPRINT | AQ12: Energy star 8.0 FSC Mix TCO Certified RoHS REACH | AR12: US MIL-STD 810H military-grade standard | AT12: LED Backlit
A13: =IF(ISBLANK(I13),"",H13) -> 90NX | B13: =IF(ISBLANK(I13),"",I13) -> B1402CBA_ID-NK7850X | C13: =IF(ISBLANK(I13),"",IF(LEFT(H13, 4) = "90PF",_xlfn.XLOOKUP(B13,'Auto-PF'!$A$2:$A$500,'Auto-PF'!$B$2:$B$500,"Not found",0),_xlfn.XLOOKUP(LEFT(B13,5),'MKT name rule'!$B$2:$B$322,'MKT name rule'!$C$2:$C$322, "Not found"))) -> ASUS ExpertBook B1 | D13: Primed to perform. Configured for your bussiness. | F13: https://drive.google.com/drive/folders/1Vo1jpHMCrMBRrGxqaMBYjJYY4bfRUZ8K?usp=drive_link | H13: 90NX | I13: B1402CBA_ID-NK7850X | J13: VSNX06V1-BU1000 | K13: Intel® Core™ i7-1255U Processor 1.7 GHz (12M Cache, up to 4.7 GHz, 10 cores) | L13: DDR4 8GB ( 8GB DDR4 on board ) | M13: 512GB 2280 PCIE G4 SSD | N13: Intel® UHD Graphics | O13: Windows 11 Pro 1-month trial for new Microsoft 365 customers. Credit card required. | P13: M365 FREE TRIAL 30D(WW) | Q13: LCD Cover: Star Black, Plastic Top Case: Star Black, Plastic | R13: 1x DDR4 SO-DIMM slot 1x M.2 2280 PCIe 4.0x4 | S13: Front: 720p HD camera Rear: - With privacy shutter World-Facing: - | T13: Audio by Dirac Built-in speaker Built-in array microphone | U13: Wi-Fi 6(802.11ax) (Dual band) 2*2 + Bluetooth® 5.2 Wireless Card | V13: 1x USB 2.0 Type-A 1x USB 3.2 Gen 1 Type-A 1x USB 3.2 Gen 1 Type-C support power delivery 1x USB 3.2 Gen 2 Type-C support display / power delivery 1x HDMI 1.4, up to 1920x1080p/60Hz 1x 3.5mm Combo Audio Jack 1x RJ45 Gigabit Ethernet | W13: FingerPrint BIOS Booting User Password Protection BIOS setup user password HDD User Password Protection and Security Support Absolute Persistence 2.0 (Computrace) Trusted Platform Module (TPM) 2.0 Fingerprint sensor intergrated with Touchpad Kensington Nano Security Slot™(6x 2.5mm) | X13: Backpack Carry bag USB-C to USB-C cable | Y13: 14.0 | Z13: LED Back-lit-Narrow border | AA13: 250nits | AB13: FHD 1920X1080 16:9 | AC13: Anti-Glare | AD13: NTSC:45% | AE13: non-Touch | AG13: ID,1Y CARRY-IN(ADP)+2Y CARRY-IN | AH13: 1.499 Kg | AI13: 1.335 | AJ13: 32.69 x 21.45 x 1.99 ~ 1.99 cm (12.87" x 8.44" x 0.78" ~ 0.78") | AK13: 42WHrs, 3S1P, 3-cell Li-ion | AL13: TYPE-C, 65W AC Adapter, Output: 20V DC, 3.25A, 65W, Input: 100~240V AC 50/60Hz universal | AN13: N/A | AO13: Backlit Chiclet Keyboard | AP13: W/FINGERPRINT | AQ13: EPEAT Gold Energy star 8.0 FSC Mix RoHS REACH | AR13: US MIL-STD 810H military-grade standard | AT13: LED Backlit
A14: =IF(ISBLANK(I14),"",H14) -> 90PT03X5-M00PT0 | B14: =IF(ISBLANK(I14),"",I14) -> P440VAK-B3820W | C14: =IF(ISBLANK(I14),"",IF(LEFT(H14, 4) = "90PF",_xlfn.XLOOKUP(B14,'Auto-PF'!$A$2:$A$500,'Auto-PF'!$B$2:$B$500,"Not found",0),_xlfn.XLOOKUP(LEFT(B14,5),'MKT name rule'!$B$2:$B$322,'MKT name rule'!$C$2:$C$322, "Not found"))) -> ASUS ExpertCenter P400 | D14: Trusted by IT Experts. Built for Worry-Free Business. | E14: - Business-Class Performance in a Sleek Design with 93% Screen-to-Body Ratio and 100Hz Responsive Touchscreen - Optimized for Hybrid Work with AI ExpertMeet and Immersive Dolby Audio - Enterprise-Grade Security and Reliability with TPM 2.0, Retractable Camera, and 2-Year Full Warranty with Accidental Damage Protection | F14: https://drive.google.com/drive/folders/10xdgtOv0R7bSoWtrRvzKjkLQLG3yJp-u?usp=drive_link | H14: 90PT03X5-M00PT0 | I14: P440VAK-B3820W | J14: 4711387957653 | K14: Intel® Core™ i3-1315U Processor 1.2 GHz (10M Cache, up to 4.5 GHz, 6 cores) | L14: 2.202 | M14: VSPT03X3-BU0180 | N14: Black | O14: 23.8-inch | P14: FHD (1920 x 1080) 16:9 | Q14: LCD | R14: 250nits | S14: sRGB: 100% | T14: 178/178 | U14: 14/25 | V14: 100Hz | W14: 1000:1 | X14: 93 % | Y14: Wide view | Z14: Anti-glare display | AA14: Non-touch screen | AB14: Normal Stand | AC14: Intel® Core™ i3-1315U Processor 1.2 GHz (10M Cache, up to 4.5 GHz, 6 cores) | AD14: N/A | AE14: N/A | AF14: Intel® Graphics | AG14: 8GB DDR5 SO-DIMM | AH14: DDR5 8GB | AI14: 256GB M.2 NVMe™ PCIe® 4.0 SSD | AJ14: 2x DDR5 SO-DIMM slot | AK14: Not available | AL14: Wi-Fi 6(802.11ax) (Dual band) 2*2 + Bluetooth® 5.4 Wireless Card | AM14: Realtek RTL8111H 10/100/1000 Mbps | AN14: 1080p FHD camera | AO14: With privacy shutter | AP14: N/A | AQ14: Built-in array microphone Built-in speakers | AR14: Windows 11 Home | AS14: 1-month trial for new Microsoft 365 customers. Credit card required. | AT14: ø4.5, 90W AC Adapter, Output: 19V DC, 4.74A, 90W, Input: 100~240V AC 50/60Hz universal | AU14: 1x Kensington lock 1x 3.5mm combo audio jack 1x USB 2.0 Type-A | AV14: 1x DC-in 1x RJ45 Gigabit Ethernet 1x HDMI out 1.4 1x USB 3.2 Gen 1 Type-C 3x USB 3.2 Gen 1 Type-A | AW14: 54.1 x 41.6 x 1.7 ~ 21.0 cm (21.30" x 16.38" x 0.67" ~ 8.27") | AX14: 06.90 kg (15.21 lbs) | AY14: BIOS Booting User Password Protection HDD User Password Protection and Security Kensington Security Slot™(7x 3mm) | AZ14: McAfee® 30 days free trial | BA14: Trusted Platform Module (TPM) 2.0 | BB14: MyASUS ASUS Business Manager AI ExpertMeet (AI features need devices with 12GB RAM or more) | BC14: System diagnosis Fan Profile Splendid AppDeals Link to MyASUS | BD14: Wired black keyboard (USB) Wired optical mouse (USB) | BE14: EPEAT Gold Energy star 8.0 REACH RoHS | BF14: ACCX002-04PE//1Y Extension ACX11-00481DPT//2Y Extension ACX11-00482DPT//3Y Extension ACX12-002742PT//2Y Accidental Damage Protection* ACX12-002752PT//1Y Extension 3Y Accidental Damage Protection* *upgrade ACX12-002782PT//2Y Extension 4Y Accidental Damage Protection* *upgrade ACX12-002792PT//3Y Extension 5Y Accidental Damage Protection**upgrade ACX13-007990PT//3Y Extension 5Y OnSite Service*upgrade ACX13-0079A0PT//1Y Extension 3Y OnSite Service*upgrade ACX13-0079C0PT//2Y OnSite Service*upgrade ACX13-0079H0PT//2Y Extension 4Y OnSite Service*upgrade ACX15-021900PT//2Y OnSite Service 2Y Accidental Damage Protection* 2Y HDD_Retention*upgrade ACX15-021910PT//1Y Extension 3Y OnSite Service 3Y Accidental Damage Protection* 3Y HDD_Retention*upgrade ACX15-021920PT//2Y Extension 4Y OnSite Service 4Y Accidental Damage Protection* 4Y HDD_Retention*upgrade ACX15-021930PT//3Y Extension 5Y OnSite Service 5Y Accidental Damage Protection* 5Y HDD_Retention*upgrade | BG14: 65% PCR recycled plastic rear cover | BH14: 65% PCR recycled plastic base cover | BI14: 55%
A15: =IF(ISBLANK(I15),"",H15) -> 90PT03X5-M01380 | B15: =IF(ISBLANK(I15),"",I15) -> P440VAK-B3850W | C15: =IF(ISBLANK(I15),"",IF(LEFT(H15, 4) = "90PF",_xlfn.XLOOKUP(B15,'Auto-PF'!$A$2:$A$500,'Auto-PF'!$B$2:$B$500,"Not found",0),_xlfn.XLOOKUP(LEFT(B15,5),'MKT name rule'!$B$2:$B$322,'MKT name rule'!$C$2:$C$322, "Not found"))) -> ASUS ExpertCenter P400 | D15: Trusted by IT Experts. Built for Worry-Free Business. | E15: - Business-Class Performance in a Sleek Design with 93% Screen-to-Body Ratio and 100Hz Responsive Touchscreen - Optimized for Hybrid Work with AI ExpertMeet and Immersive Dolby Audio - Enterprise-Grade Security and Reliability with TPM 2.0, Retractable Camera, and 2-Year Full Warranty with Accidental Damage Protection | F15: https://drive.google.com/drive/folders/1BYBp7cwSevZJbrAM9yVaCn0-RP8wxtt5?usp=drive_link | H15: 90PT03X5-M01380 | I15: P440VAK-B3850W | J15: 4711387957660 | K15: 197105957664 | L15: 2.202 | M15: VSPT03X3-BU0180 | N15: Black | O15: 23.8-inch | P15: FHD (1920 x 1080) 16:9 | Q15: LCD | R15: 250nits | S15: sRGB: 100% | T15: 178/178 | U15: 14/25 | V15: 100Hz | W15: 1000:1 | X15: 93 % | Y15: Wide view | Z15: Anti-glare display | AA15: Non-touch screen | AB15: Normal Stand | AC15: Intel® Core™ i3-1315U Processor 1.2 GHz (10M Cache, up to 4.5 GHz, 6 cores) | AD15: N/A | AE15: N/A | AF15: Intel® Graphics | AG15: 8GB DDR5 SO-DIMM | AH15: DDR5 8GB | AI15: 512GB M.2 NVMe™ PCIe® 4.0 SSD | AJ15: 2x DDR5 SO-DIMM slot | AK15: Not available | AL15: Wi-Fi 6(802.11ax) (Dual band) 2*2 + Bluetooth® 5.4 Wireless Card | AM15: Realtek RTL8111H 10/100/1000 Mbps | AN15: 1080p FHD camera | AO15: With privacy shutter | AP15: N/A | AQ15: Built-in array microphone Built-in speakers | AR15: Windows 11 Home - ASUS recommends Windows 11 Pro for business | AS15: 1-month trial for new Microsoft 365 customers. Credit card required. | AT15: ø4.5, 90W AC Adapter, Output: 19V DC, 4.74A, 90W, Input: 100~240V AC 50/60Hz universal | AU15: 1x Kensington lock 1x 3.5mm combo audio jack 1x USB 2.0 Type-A | AV15: 1x DC-in 1x RJ45 Gigabit Ethernet 1x HDMI out 1.4 1x USB 3.2 Gen 1 Type-C 3x USB 3.2 Gen 1 Type-A | AW15: 54.1 x 41.6 x 1.7 ~ 21.0 cm (21.30" x 16.38" x 0.67" ~ 8.27") | AX15: 06.90 kg (15.21 lbs) | AY15: BIOS Booting User Password Protection HDD User Password Protection and Security Kensington Security Slot™(7x 3mm) | AZ15: McAfee® 30 days free trial | BA15: Trusted Platform Module (TPM) 2.0 | BB15: MyASUS ASUS Business Manager AI ExpertMeet (AI features need devices with 12GB RAM or more) | BC15: System diagnosis Fan Profile Splendid AppDeals Link to MyASUS | BD15: Wired black keyboard (USB) Wired optical mouse (USB) | BE15: EPEAT Gold Energy star 8.0 REACH RoHS | BF15: ACCX002-04PE//1Y Extension ACX11-00481DPT//2Y Extension ACX11-00482DPT//3Y Extension ACX12-002742PT//2Y Accidental Damage Protection* ACX12-002752PT//1Y Extension 3Y Accidental Damage Protection* *upgrade ACX12-002782PT//2Y Extension 4Y Accidental Damage Protection* *upgrade ACX12-002792PT//3Y Extension 5Y Accidental Damage Protection**upgrade ACX13-007990PT//3Y Extension 5Y OnSite Service*upgrade ACX13-0079A0PT//1Y Extension 3Y OnSite Service*upgrade ACX13-0079C0PT//2Y OnSite Service*upgrade ACX13-0079H0PT//2Y Extension 4Y OnSite Service*upgrade ACX15-021900PT//2Y OnSite Service 2Y Accidental Damage Protection* 2Y HDD_Retention*upgrade ACX15-021910PT//1Y Extension 3Y OnSite Service 3Y Accidental Damage Protection* 3Y HDD_Retention*upgrade ACX15-021920PT//2Y Extension 4Y OnSite Service 4Y Accidental Damage Protection* 4Y HDD_Retention*upgrade ACX15-021930PT//3Y Extension 5Y OnSite Service 5Y Accidental Damage Protection* 5Y HDD_Retention*upgrade | BG15: 65% PCR recycled plastic rear cover | BH15: 65% PCR recycled plastic base cover | BI15: 55%
A16: =IF(ISBLANK(I16),"",H16) -> 90PT03X5-M01390 | B16: =IF(ISBLANK(I16),"",I16) -> P440VAK-B3850WS | C16: =IF(ISBLANK(I16),"",IF(LEFT(H16, 4) = "90PF",_xlfn.XLOOKUP(B16,'Auto-PF'!$A$2:$A$500,'Auto-PF'!$B$2:$B$500,"Not found",0),_xlfn.XLOOKUP(LEFT(B16,5),'MKT name rule'!$B$2:$B$322,'MKT name rule'!$C$2:$C$322, "Not found"))) -> ASUS ExpertCenter P400 | D16: Trusted by IT Experts. Built for Worry-Free Business. | E16: - Business-Class Performance in a Sleek Design with 93% Screen-to-Body Ratio and 100Hz Responsive Touchscreen - Optimized for Hybrid Work with AI ExpertMeet and Immersive Dolby Audio - Enterprise-Grade Security and Reliability with TPM 2.0, Retractable Camera, and 2-Year Full Warranty with Accidental Damage Protection | F16: https://drive.google.com/drive/folders/1UWtVSqNA3WLpBdSbrf0UatcpdnjHKzpG?usp=drive_link | H16: 90PT03X5-M01390 | I16: P440VAK-B3850WS | J16: 4711636034395 | K16: 199291034396 | L16: 2.202 | M16: VSPT03X3-BU0180 | N16: Black | O16: 23.8-inch | P16: FHD (1920 x 1080) 16:9 | Q16: LCD | R16: 250nits | S16: sRGB: 100% | T16: 178/178 | U16: 14/25 | V16: 100Hz | W16: 1000:1 | X16: 93 % | Y16: Wide view | Z16: Anti-glare display | AA16: Non-touch screen | AB16: Normal Stand | AC16: Intel® Core™ i3-1315U Processor 1.2 GHz (10M Cache, up to 4.5 GHz, 6 cores) | AD16: N/A | AE16: N/A | AF16: Intel® Graphics | AG16: 8GB DDR5 SO-DIMM | AH16: DDR5 8GB | AI16: 512GB M.2 NVMe™ PCIe® 4.0 SSD | AJ16: 2x DDR5 SO-DIMM slot | AK16: Not available | AL16: Wi-Fi 6(802.11ax) (Dual band) 2*2 + Bluetooth® 5.4 Wireless Card | AM16: Realtek RTL8111H 10/100/1000 Mbps | AN16: 1080p FHD camera | AO16: With privacy shutter | AP16: N/A | AQ16: Built-in array microphone Built-in speakers | AR16: Windows 11 Home - ASUS recommends Windows 11 Pro for business | AS16: Microsoft Office Home 2024_x000D_ Microsoft 365 Basic | AT16: ø4.5, 90W AC Adapter, Output: 19V DC, 4.74A, 90W, Input: 100~240V AC 50/60Hz universal | AU16: 1x Kensington lock 1x 3.5mm combo audio jack 1x USB 2.0 Type-A | AV16: 1x DC-in 1x RJ45 Gigabit Ethernet 1x HDMI out 1.4 1x USB 3.2 Gen 1 Type-C 3x USB 3.2 Gen 1 Type-A | AW16: 54.1 x 41.6 x 1.7 ~ 21.0 cm (21.30" x 16.38" x 0.67" ~ 8.27") | AX16: 06.90 kg (15.21 lbs) | AY16: BIOS Booting User Password Protection HDD User Password Protection and Security Kensington Security Slot™(7x 3mm) | AZ16: McAfee® 30 days free trial | BA16: Trusted Platform Module (TPM) 2.0 | BB16: MyASUS ASUS Business Manager AI ExpertMeet (AI features need devices with 12GB RAM or more) | BC16: System diagnosis Fan Profile Splendid AppDeals Link to MyASUS | BD16: Wired black keyboard (USB) Wired optical mouse (USB) | BE16: EPEAT Gold Energy star 8.0 REACH RoHS | BF16: ACCX002-04PE//1Y Extension ACX11-00481DPT//2Y Extension ACX11-00482DPT//3Y Extension ACX12-002742PT//2Y Accidental Damage Protection* ACX12-002752PT//1Y Extension 3Y Accidental Damage Protection* *upgrade ACX12-002782PT//2Y Extension 4Y Accidental Damage Protection* *upgrade ACX12-002792PT//3Y Extension 5Y Accidental Damage Protection**upgrade ACX13-007990PT//3Y Extension 5Y OnSite Service*upgrade ACX13-0079A0PT//1Y Extension 3Y OnSite Service*upgrade ACX13-0079C0PT//2Y OnSite Service*upgrade ACX13-0079H0PT//2Y Extension 4Y OnSite Service*upgrade ACX15-021900PT//2Y OnSite Service 2Y Accidental Damage Protection* 2Y HDD_Retention*upgrade ACX15-021910PT//1Y Extension 3Y OnSite Service 3Y Accidental Damage Protection* 3Y HDD_Retention*upgrade ACX15-021920PT//2Y Extension 4Y OnSite Service 4Y Accidental Damage Protection* 4Y HDD_Retention*upgrade ACX15-021930PT//3Y Extension 5Y OnSite Service 5Y Accidental Damage Protection* 5Y HDD_Retention*upgrade | BG16: 65% PCR recycled plastic rear cover | BH16: 65% PCR recycled plastic base cover | BI16: 55%
A17: =IF(ISBLANK(I17),"",H17) -> 90PT03X5-M013A0 | B17: =IF(ISBLANK(I17),"",I17) -> P440VAK-B5850WS | C17: =IF(ISBLANK(I17),"",IF(LEFT(H17, 4) = "90PF",_xlfn.XLOOKUP(B17,'Auto-PF'!$A$2:$A$500,'Auto-PF'!$B$2:$B$500,"Not found",0),_xlfn.XLOOKUP(LEFT(B17,5),'MKT name rule'!$B$2:$B$322,'MKT name rule'!$C$2:$C$322, "Not found"))) -> ASUS ExpertCenter P400 | D17: Trusted by IT Experts. Built for Worry-Free Business. | E17: - Business-Class Performance in a Sleek Design with 93% Screen-to-Body Ratio and 100Hz Responsive Touchscreen - Optimized for Hybrid Work with AI ExpertMeet and Immersive Dolby Audio - Enterprise-Grade Security and Reliability with TPM 2.0, Retractable Camera, and 2-Year Full Warranty with Accidental Damage Protection | F17: https://drive.google.com/drive/folders/1IT3gH_MF_MbDcIGGZQd-i9xeXwR9-2cj?usp=drive_link | H17: 90PT03X5-M013A0 | I17: P440VAK-B5850WS | J17: 4711387957608 | K17: 197105957602 | L17: 2.202 | M17: VSPT03X3-BU0060 | N17: Black | O17: 23.8-inch | P17: FHD (1920 x 1080) 16:9 | Q17: LCD | R17: 250nits | S17: sRGB: 100% | T17: 178/178 | U17: 14/25 | V17: 100Hz | W17: 1000:1 | X17: 93 % | Y17: Wide view | Z17: Anti-glare display | AA17: Non-touch screen | AB17: Normal Stand | AC17: Intel® Core™ i5-13420H Processor 2.1 GHz (12MB Cache, up to 4.6 GHz, 8 cores, 12 Threads) | AD17: N/A | AE17: N/A | AF17: Intel® UHD Graphics | AG17: 8GB DDR5 SO-DIMM | AH17: DDR5 8GB | AI17: 512GB M.2 NVMe™ PCIe® 4.0 SSD | AJ17: 2x DDR5 SO-DIMM slot | AK17: Not available | AL17: Wi-Fi 6(802.11ax) (Dual band) 2*2 + Bluetooth® 5.4 Wireless Card | AM17: Realtek RTL8111H 10/100/1000 Mbps | AN17: 1080p FHD camera | AO17: With privacy shutter | AP17: N/A | AQ17: Built-in array microphone Built-in speakers | AR17: Windows 11 Home - ASUS recommends Windows 11 Pro for business | AS17: Microsoft Office Home 2024_x000D_ Microsoft 365 Basic | AT17: ø4.5, 120W AC Adapter, Output: 20V DC, 6.0A, 120W, Input: 100~240V AC 50/60Hz universal | AU17: 1x Kensington lock 1x 3.5mm combo audio jack 1x USB 2.0 Type-A | AV17: 1x DC-in 1x RJ45 Gigabit Ethernet 1x HDMI in 1.4 1x HDMI out 1.4 1x USB 3.2 Gen 1 Type-C 3x USB 3.2 Gen 1 Type-A | AW17: 54.1 x 41.6 x 1.7 ~ 21.0 cm (21.30" x 16.38" x 0.67" ~ 8.27") | AX17: 06.90 kg (15.21 lbs) | AY17: BIOS Booting User Password Protection HDD User Password Protection and Security Kensington Security Slot™(7x 3mm) | AZ17: McAfee® 30 days free trial | BA17: Trusted Platform Module (TPM) 2.0 | BB17: MyASUS ASUS Business Manager AI ExpertMeet (AI features need devices with 12GB RAM or more) | BC17: System diagnosis Fan Profile Splendid AppDeals Link to MyASUS | BD17: Wired black keyboard (USB) Wired optical mouse (USB) | BE17: EPEAT Gold Energy star 8.0 REACH RoHS | BF17: ACCX002-04PE//1Y Extension ACX11-00481DPT//2Y Extension ACX11-00482DPT//3Y Extension ACX12-002742PT//2Y Accidental Damage Protection* ACX12-002752PT//1Y Extension 3Y Accidental Damage Protection* *upgrade ACX12-002782PT//2Y Extension 4Y Accidental Damage Protection* *upgrade ACX12-002792PT//3Y Extension 5Y Accidental Damage Protection**upgrade ACX13-007990PT//3Y Extension 5Y OnSite Service*upgrade ACX13-0079A0PT//1Y Extension 3Y OnSite Service*upgrade ACX13-0079C0PT//2Y OnSite Service*upgrade ACX13-0079H0PT//2Y Extension 4Y OnSite Service*upgrade ACX15-021900PT//2Y OnSite Service 2Y Accidental Damage Protection* 2Y HDD_Retention*upgrade ACX15-021910PT//1Y Extension 3Y OnSite Service 3Y Accidental Damage Protection* 3Y HDD_Retention*upgrade ACX15-021920PT//2Y Extension 4Y OnSite Service 4Y Accidental Damage Protection* 4Y HDD_Retention*upgrade ACX15-021930PT//3Y Extension 5Y OnSite Service 5Y Accidental Damage Protection* 5Y HDD_Retention*upgrade | BG17: 65% PCR recycled plastic rear cover | BH17: 65% PCR recycled plastic base cover | BI17: 55%
A18: =IF(ISBLANK(I18),"",H18) -> 90PT03X5-M013B0 | B18: =IF(ISBLANK(I18),"",I18) -> P440VAK-B5150WS | C18: =IF(ISBLANK(I18),"",IF(LEFT(H18, 4) = "90PF",_xlfn.XLOOKUP(B18,'Auto-PF'!$A$2:$A$500,'Auto-PF'!$B$2:$B$500,"Not found",0),_xlfn.XLOOKUP(LEFT(B18,5),'MKT name rule'!$B$2:$B$322,'MKT name rule'!$C$2:$C$322, "Not found"))) -> ASUS ExpertCenter P400 | D18: Trusted by IT Experts. Built for Worry-Free Business. | E18: - Business-Class Performance in a Sleek Design with 93% Screen-to-Body Ratio and 100Hz Responsive Touchscreen - Optimized for Hybrid Work with AI ExpertMeet and Immersive Dolby Audio - Enterprise-Grade Security and Reliability with TPM 2.0, Retractable Camera, and 2-Year Full Warranty with Accidental Damage Protection | F18: https://drive.google.com/drive/folders/1zCAw9ldJMBVNot4g29o7hNP8Ep3Nc46X?usp=drive_link | H18: 90PT03X5-M013B0 | I18: P440VAK-B5150WS | L18: 2.25 | M18: VSPT03X3-BU0060 | N18: Black | O18: 23.8-inch | P18: FHD (1920 x 1080) 16:9 | Q18: LCD | R18: 250nits | S18: sRGB: 100% | T18: 178/178 | U18: 14/25 | V18: 100Hz | W18: 1000:1 | X18: 93 % | Y18: Wide view | Z18: Anti-glare display | AA18: Non-touch screen | AB18: Normal Stand | AC18: Intel® Core™ i5-13420H Processor 2.1 GHz (12MB Cache, up to 4.6 GHz, 8 cores, 12 Threads) | AD18: N/A | AE18: N/A | AF18: Intel® UHD Graphics | AG18: 16GB DDR5 SO-DIMM | AH18: DDR5 16GB | AI18: 512GB M.2 NVMe™ PCIe® 4.0 SSD | AJ18: 2x DDR5 SO-DIMM slot | AK18: Not available | AL18: Wi-Fi 6(802.11ax) (Dual band) 2*2 + Bluetooth® 5.4 Wireless Card | AM18: Realtek RTL8111H 10/100/1000 Mbps | AN18: 1080p FHD camera | AO18: With privacy shutter | AP18: N/A | AQ18: Built-in array microphone Built-in speakers | AR18: Windows 11 Home - ASUS recommends Windows 11 Pro for business | AS18: Microsoft Office Home 2024_x000D_ Microsoft 365 Basic | AT18: ø4.5, 120W AC Adapter, Output: 20V DC, 6.0A, 120W, Input: 100~240V AC 50/60Hz universal | AU18: 1x Kensington lock 1x 3.5mm combo audio jack 1x USB 2.0 Type-A | AV18: 1x DC-in 1x RJ45 Gigabit Ethernet 1x HDMI in 1.4 1x HDMI out 1.4 1x USB 3.2 Gen 1 Type-C 3x USB 3.2 Gen 1 Type-A | AW18: 54.1 x 41.6 x 1.7 ~ 21.0 cm (21.30" x 16.38" x 0.67" ~ 8.27") | AX18: 06.90 kg (15.21 lbs) | AY18: BIOS Booting User Password Protection HDD User Password Protection and Security Kensington Security Slot™(7x 3mm) | AZ18: McAfee® 30 days free trial | BA18: Trusted Platform Module (TPM) 2.0 | BB18: MyASUS ASUS Business Manager AI ExpertMeet (AI features need devices with 12GB RAM or more) | BC18: System diagnosis Fan Profile Splendid AppDeals Link to MyASUS | BD18: Wired black keyboard (USB) Wired optical mouse (USB) | BE18: EPEAT Gold Energy star 8.0 REACH RoHS | BF18: ACCX002-04PE//1Y Extension ACX11-00481DPT//2Y Extension ACX11-00482DPT//3Y Extension ACX12-002742PT//2Y Accidental Damage Protection* ACX12-002752PT//1Y Extension 3Y Accidental Damage Protection* *upgrade ACX12-002782PT//2Y Extension 4Y Accidental Damage Protection* *upgrade ACX12-002792PT//3Y Extension 5Y Accidental Damage Protection**upgrade ACX13-007990PT//3Y Extension 5Y OnSite Service*upgrade ACX13-0079A0PT//1Y Extension 3Y OnSite Service*upgrade ACX13-0079C0PT//2Y OnSite Service*upgrade ACX13-0079H0PT//2Y Extension 4Y OnSite Service*upgrade ACX15-021900PT//2Y OnSite Service 2Y Accidental Damage Protection* 2Y HDD_Retention*upgrade ACX15-021910PT//1Y Extension 3Y OnSite Service 3Y Accidental Damage Protection* 3Y HDD_Retention*upgrade ACX15-021920PT//2Y Extension 4Y OnSite Service 4Y Accidental Damage Protection* 4Y HDD_Retention*upgrade ACX15-021930PT//3Y Extension 5Y OnSite Service 5Y Accidental Damage Protection* 5Y HDD_Retention*upgrade | BG18: 65% PCR recycled plastic rear cover | BH18: 65% PCR recycled plastic base cover | BI18: 55%
